[25/Feb/2019 13:43:16] INFO [ai.classifier] [__init__:15] Classifier created: mock
[25/Feb/2019 13:43:33] INFO [django.server] [log_message:154] "GET / HTTP/1.1" 200 401
[25/Feb/2019 13:43:33] INFO [django.server] [log_message:154] "GET / HTTP/1.1" 200 401
[25/Feb/2019 13:43:35] WARNING [django.request] [log_response:228] Not Found: /favicon.ico
[25/Feb/2019 13:43:35] WARNING [django.server] [log_message:154] "GET /favicon.ico HTTP/1.1" 404 2565
[25/Feb/2019 13:43:35] WARNING [django.server] [log_message:154] "GET /favicon.ico HTTP/1.1" 404 2565
[25/Feb/2019 13:44:11] INFO [django.server] [log_message:154] "GET /accounts/login/ HTTP/1.1" 200 1566
[25/Feb/2019 13:44:11] INFO [django.server] [log_message:154] "GET /accounts/login/ HTTP/1.1" 200 1566
[25/Feb/2019 13:44:11] INFO [django.server] [log_message:154] "POST /accounts/login/ HTTP/1.1" 302 0
[25/Feb/2019 13:44:11] INFO [django.server] [log_message:154] "POST /accounts/login/ HTTP/1.1" 302 0
[25/Feb/2019 13:44:12] ERROR [django.request] [log_response:228] Internal Server Error: /users/profile/
Traceback (most recent call last):
  File "C:\Python36\lib\site-packages\django\core\handlers\exception.py", line 34, in inner
    response = get_response(request)
  File "C:\Python36\lib\site-packages\django\utils\deprecation.py", line 93, in __call__
    response = self.process_response(request, response)
  File "C:\Python36\lib\site-packages\django\middleware\clickjacking.py", line 26, in process_response
    if response.get('X-Frame-Options') is not None:
  File "C:\Python36\lib\site-packages\django\utils\functional.py", line 214, in inner
    return func(self._wrapped, *args)
AttributeError: 'CustomUser' object has no attribute 'get'
[25/Feb/2019 13:44:12] ERROR [django.server] [log_message:154] "GET /users/profile/ HTTP/1.1" 500 68024
[25/Feb/2019 13:44:12] ERROR [django.server] [log_message:154] "GET /users/profile/ HTTP/1.1" 500 68024
[25/Feb/2019 13:44:12] INFO [ai.classification] [find_creator_and_verify_permissions:29] szabag@gmail.com requested a new classification
[25/Feb/2019 13:44:12] INFO [ai.classification] [save_picture_and_create_imagedata:34] Processing image file data 430.jpg 
[25/Feb/2019 13:44:12] INFO [ai.classification] [save_picture_and_create_imagedata:43] New imagefile saved with id 6 
[25/Feb/2019 13:44:12] INFO [ai.classification] [save_picture_and_create_imagedata:54] Image saved into C:\CR\IMAGES\szabag\ 
[25/Feb/2019 13:44:12] INFO [django.server] [log_message:154] "POST /core/classify/ HTTP/1.1" 200 3
[25/Feb/2019 13:44:12] INFO [django.server] [log_message:154] "POST /core/classify/ HTTP/1.1" 200 3
