[25/Feb/2019 14:46:39] DEBUG [core.models] [mockit:175] Mocking done
[25/Feb/2019 14:46:39] INFO [ai.classifier] [__init__:15] Classifier created: mock
[25/Feb/2019 14:47:05] INFO [django.server] [log_message:154] "GET /accounts/login/ HTTP/1.1" 200 1566
[25/Feb/2019 14:47:05] INFO [django.server] [log_message:154] "GET /accounts/login/ HTTP/1.1" 200 1566
[25/Feb/2019 14:47:06] INFO [django.server] [log_message:154] "POST /accounts/login/ HTTP/1.1" 302 0
[25/Feb/2019 14:47:06] INFO [django.server] [log_message:154] "POST /accounts/login/ HTTP/1.1" 302 0
[25/Feb/2019 14:47:06] ERROR [django.request] [log_response:228] Internal Server Error: /users/profile/
Traceback (most recent call last):
  File "C:\Python36\lib\site-packages\django\core\handlers\exception.py", line 34, in inner
    response = get_response(request)
  File "C:\Python36\lib\site-packages\django\utils\deprecation.py", line 93, in __call__
    response = self.process_response(request, response)
  File "C:\Python36\lib\site-packages\django\middleware\clickjacking.py", line 26, in process_response
    if response.get('X-Frame-Options') is not None:
  File "C:\Python36\lib\site-packages\django\utils\functional.py", line 214, in inner
    return func(self._wrapped, *args)
AttributeError: 'CustomUser' object has no attribute 'get'
[25/Feb/2019 14:47:06] ERROR [django.server] [log_message:154] "GET /users/profile/ HTTP/1.1" 500 69986
[25/Feb/2019 14:47:06] ERROR [django.server] [log_message:154] "GET /users/profile/ HTTP/1.1" 500 69986
[25/Feb/2019 14:47:08] INFO [core.views] [post:30] Some files are in the request, processing started..
[25/Feb/2019 14:47:08] INFO [ai.classification] [find_creator_and_verify_permissions:30] szabag@gmail.com requested a new classification
[25/Feb/2019 14:47:08] INFO [ai.classification] [save_picture_and_create_imagedata:35] Processing image file data 430.jpg 
[25/Feb/2019 14:47:08] INFO [ai.classification] [save_picture_and_create_imagedata:44] New imagefile saved with id 9 
[25/Feb/2019 14:47:08] INFO [ai.classification] [save_picture_and_create_imagedata:55] Image saved into C:\CR\IMAGES\szabag\ 
[25/Feb/2019 14:47:08] INFO [ai.classification] [classify:61] Classification started for image 430 by user szabag
[25/Feb/2019 14:47:08] INFO [ai.classification] [classify:72] New classification created with id 9
[25/Feb/2019 14:47:10] INFO [ai.classifier] [classify:18] Classifying image: 430
[25/Feb/2019 14:47:10] DEBUG [ai.classifier] [classify:19] MOCKED CLASSIFICATION!
[25/Feb/2019 14:47:10] INFO [core.models] [add_result:78] Adding new classification result
[25/Feb/2019 14:47:10] INFO [core.models] [results:68] Getting classification results
[25/Feb/2019 14:47:10] DEBUG [core.models] [results:70] 0 results founded
[25/Feb/2019 14:47:10] INFO [core.models] [add_result:85] Classification result saved with id 2
[25/Feb/2019 14:47:10] INFO [ai.classifier] [classify:25] New Classification result created
[25/Feb/2019 14:47:10] INFO [core.models] [add_car:140] Adding new classification result car
[25/Feb/2019 14:47:10] INFO [core.models] [cars:130] Getting classification result cars
[25/Feb/2019 14:47:10] DEBUG [core.models] [cars:132] 0 classification cars founded
[25/Feb/2019 14:47:10] INFO [core.models] [add_car:147] Classification result car saved with id 6
[25/Feb/2019 14:47:10] INFO [core.models] [add_car:140] Adding new classification result car
[25/Feb/2019 14:47:10] INFO [core.models] [add_car:147] Classification result car saved with id 7
[25/Feb/2019 14:47:10] INFO [core.models] [add_car:140] Adding new classification result car
[25/Feb/2019 14:47:10] INFO [core.models] [add_car:147] Classification result car saved with id 8
[25/Feb/2019 14:47:10] INFO [ai.classifier] [classify:30] Classification cars saved..
[25/Feb/2019 14:47:15] INFO [ai.classification] [classify:76] Classification ended at: 5.63680362701416
[25/Feb/2019 14:47:17] INFO [django.server] [log_message:154] "POST /core/classify/ HTTP/1.1" 200 31
[25/Feb/2019 14:47:17] INFO [django.server] [log_message:154] "POST /core/classify/ HTTP/1.1" 200 31
[25/Feb/2019 14:47:36] INFO [django.server] [log_message:154] "GET /accounts/login/ HTTP/1.1" 200 1566
[25/Feb/2019 14:47:36] INFO [django.server] [log_message:154] "GET /accounts/login/ HTTP/1.1" 200 1566
[25/Feb/2019 14:47:37] INFO [django.server] [log_message:154] "POST /accounts/login/ HTTP/1.1" 302 0
[25/Feb/2019 14:47:37] INFO [django.server] [log_message:154] "POST /accounts/login/ HTTP/1.1" 302 0
[25/Feb/2019 14:47:37] ERROR [django.request] [log_response:228] Internal Server Error: /users/profile/
Traceback (most recent call last):
  File "C:\Python36\lib\site-packages\django\core\handlers\exception.py", line 34, in inner
    response = get_response(request)
  File "C:\Python36\lib\site-packages\django\utils\deprecation.py", line 93, in __call__
    response = self.process_response(request, response)
  File "C:\Python36\lib\site-packages\django\middleware\clickjacking.py", line 26, in process_response
    if response.get('X-Frame-Options') is not None:
  File "C:\Python36\lib\site-packages\django\utils\functional.py", line 214, in inner
    return func(self._wrapped, *args)
AttributeError: 'CustomUser' object has no attribute 'get'
[25/Feb/2019 14:47:37] ERROR [django.server] [log_message:154] "GET /users/profile/ HTTP/1.1" 500 69986
[25/Feb/2019 14:47:37] ERROR [django.server] [log_message:154] "GET /users/profile/ HTTP/1.1" 500 69986
[25/Feb/2019 14:47:42] INFO [core.views] [post:30] Some files are in the request, processing started..
[25/Feb/2019 14:47:42] INFO [ai.classification] [find_creator_and_verify_permissions:30] szabag@gmail.com requested a new classification
[25/Feb/2019 14:47:42] INFO [ai.classification] [save_picture_and_create_imagedata:35] Processing image file data 430.jpg 
[25/Feb/2019 14:47:42] INFO [ai.classification] [save_picture_and_create_imagedata:44] New imagefile saved with id 10 
[25/Feb/2019 14:47:42] INFO [ai.classification] [save_picture_and_create_imagedata:55] Image saved into C:\CR\IMAGES\szabag\ 
[25/Feb/2019 14:47:42] INFO [ai.classification] [classify:61] Classification started for image 430 by user szabag
[25/Feb/2019 14:47:42] INFO [ai.classification] [classify:72] New classification created with id 10
[25/Feb/2019 14:47:45] INFO [ai.classifier] [classify:18] Classifying image: 430
[25/Feb/2019 14:47:45] DEBUG [ai.classifier] [classify:19] MOCKED CLASSIFICATION!
[25/Feb/2019 14:47:45] INFO [core.models] [add_result:78] Adding new classification result
[25/Feb/2019 14:47:45] INFO [core.models] [results:68] Getting classification results
[25/Feb/2019 14:47:45] DEBUG [core.models] [results:70] 0 results founded
[25/Feb/2019 14:47:45] INFO [core.models] [add_result:85] Classification result saved with id 3
[25/Feb/2019 14:47:45] INFO [ai.classifier] [classify:25] New Classification result created
[25/Feb/2019 14:47:45] INFO [core.models] [add_car:140] Adding new classification result car
[25/Feb/2019 14:47:45] INFO [core.models] [cars:130] Getting classification result cars
[25/Feb/2019 14:47:45] DEBUG [core.models] [cars:132] 0 classification cars founded
[25/Feb/2019 14:47:45] INFO [core.models] [add_car:147] Classification result car saved with id 9
[25/Feb/2019 14:47:45] INFO [core.models] [add_car:140] Adding new classification result car
[25/Feb/2019 14:47:45] INFO [core.models] [add_car:147] Classification result car saved with id 10
[25/Feb/2019 14:47:45] INFO [core.models] [add_car:140] Adding new classification result car
[25/Feb/2019 14:47:45] INFO [core.models] [add_car:147] Classification result car saved with id 11
[25/Feb/2019 14:47:45] INFO [ai.classifier] [classify:30] Classification cars saved..
[25/Feb/2019 14:47:47] INFO [ai.classification] [classify:76] Classification ended at: 5.0737621784210205
[25/Feb/2019 14:47:47] INFO [django.server] [log_message:154] "POST /core/classify/ HTTP/1.1" 200 31
[25/Feb/2019 14:47:47] INFO [django.server] [log_message:154] "POST /core/classify/ HTTP/1.1" 200 31
