[25/Feb/2019 14:19:58] DEBUG [core.models] [mockit:166] Mocking done
[25/Feb/2019 14:19:59] INFO [ai.classifier] [__init__:15] Classifier created: mock
[25/Feb/2019 14:20:02] INFO [django.server] [log_message:154] "GET /accounts/login/ HTTP/1.1" 200 1566
[25/Feb/2019 14:20:02] INFO [django.server] [log_message:154] "GET /accounts/login/ HTTP/1.1" 200 1566
[25/Feb/2019 14:20:02] INFO [django.server] [log_message:154] "POST /accounts/login/ HTTP/1.1" 302 0
[25/Feb/2019 14:20:02] INFO [django.server] [log_message:154] "POST /accounts/login/ HTTP/1.1" 302 0
[25/Feb/2019 14:20:02] ERROR [django.request] [log_response:228] Internal Server Error: /users/profile/
Traceback (most recent call last):
  File "C:\Python36\lib\site-packages\django\core\handlers\exception.py", line 34, in inner
    response = get_response(request)
  File "C:\Python36\lib\site-packages\django\utils\deprecation.py", line 93, in __call__
    response = self.process_response(request, response)
  File "C:\Python36\lib\site-packages\django\middleware\clickjacking.py", line 26, in process_response
    if response.get('X-Frame-Options') is not None:
  File "C:\Python36\lib\site-packages\django\utils\functional.py", line 214, in inner
    return func(self._wrapped, *args)
AttributeError: 'CustomUser' object has no attribute 'get'
[25/Feb/2019 14:20:02] ERROR [django.server] [log_message:154] "GET /users/profile/ HTTP/1.1" 500 69983
[25/Feb/2019 14:20:02] ERROR [django.server] [log_message:154] "GET /users/profile/ HTTP/1.1" 500 69983
[25/Feb/2019 14:20:04] INFO [core.views] [post:30] Some files are in the request, processing started..
[25/Feb/2019 14:20:04] INFO [ai.classification] [find_creator_and_verify_permissions:30] szabag@gmail.com requested a new classification
[25/Feb/2019 14:20:04] INFO [ai.classification] [save_picture_and_create_imagedata:35] Processing image file data 430.jpg 
[25/Feb/2019 14:20:04] INFO [ai.classification] [save_picture_and_create_imagedata:44] New imagefile saved with id 4 
[25/Feb/2019 14:20:04] INFO [ai.classification] [save_picture_and_create_imagedata:55] Image saved into C:\CR\IMAGES\szabag\ 
[25/Feb/2019 14:20:05] INFO [ai.classification] [classify:61] Classification started for image 430 by user szabag
[25/Feb/2019 14:20:12] INFO [ai.classification] [classify:72] New classification created with id 4
[25/Feb/2019 14:20:14] INFO [ai.classifier] [classify:18] Classifying image: 430
[25/Feb/2019 14:20:15] DEBUG [ai.classifier] [classify:19] MOCKED CLASSIFICATION!
[25/Feb/2019 14:20:32] INFO [core.models] [add_car:134] Adding new classification result car
[25/Feb/2019 14:20:34] INFO [core.models] [cars:124] Getting classification result cars
[25/Feb/2019 14:20:38] INFO [core.models] [cars:124] Getting classification result cars
[25/Feb/2019 14:20:38] DEBUG [core.models] [cars:126] 0 classification cars founded
[25/Feb/2019 14:20:40] DEBUG [core.models] [cars:126] 0 classification cars founded
