[25/Feb/2019 14:01:32] INFO [ai.classifier] [__init__:15] Classifier created: mock
[25/Feb/2019 14:01:43] INFO [django.server] [log_message:154] "GET /accounts/login/ HTTP/1.1" 200 1566
[25/Feb/2019 14:01:43] INFO [django.server] [log_message:154] "GET /accounts/login/ HTTP/1.1" 200 1566
[25/Feb/2019 14:01:43] INFO [django.server] [log_message:154] "POST /accounts/login/ HTTP/1.1" 200 1686
[25/Feb/2019 14:01:43] INFO [django.server] [log_message:154] "POST /accounts/login/ HTTP/1.1" 200 1686
[25/Feb/2019 14:01:44] INFO [django.server] [log_message:154] "POST /core/classify/ HTTP/1.1" 302 0
[25/Feb/2019 14:01:44] INFO [django.server] [log_message:154] "POST /core/classify/ HTTP/1.1" 302 0
[25/Feb/2019 14:01:44] INFO [django.server] [log_message:154] "GET /accounts/login/?next=/core/classify/ HTTP/1.1" 200 1685
[25/Feb/2019 14:01:44] INFO [django.server] [log_message:154] "GET /accounts/login/?next=/core/classify/ HTTP/1.1" 200 1685
[25/Feb/2019 14:02:13] INFO [django.server] [log_message:154] "GET /accounts/login/ HTTP/1.1" 200 1566
[25/Feb/2019 14:02:13] INFO [django.server] [log_message:154] "GET /accounts/login/ HTTP/1.1" 200 1566
[25/Feb/2019 14:02:13] INFO [django.server] [log_message:154] "POST /accounts/login/ HTTP/1.1" 200 1686
[25/Feb/2019 14:02:13] INFO [django.server] [log_message:154] "POST /accounts/login/ HTTP/1.1" 200 1686
[25/Feb/2019 14:02:13] INFO [django.server] [log_message:154] "POST /core/classify/ HTTP/1.1" 302 0
[25/Feb/2019 14:02:13] INFO [django.server] [log_message:154] "POST /core/classify/ HTTP/1.1" 302 0
[25/Feb/2019 14:02:14] INFO [django.server] [log_message:154] "GET /accounts/login/?next=/core/classify/ HTTP/1.1" 200 1685
[25/Feb/2019 14:02:14] INFO [django.server] [log_message:154] "GET /accounts/login/?next=/core/classify/ HTTP/1.1" 200 1685
[25/Feb/2019 14:02:20] INFO [django.server] [log_message:154] "GET /accounts/login/ HTTP/1.1" 200 1566
[25/Feb/2019 14:02:20] INFO [django.server] [log_message:154] "GET /accounts/login/ HTTP/1.1" 200 1566
[25/Feb/2019 14:02:21] INFO [django.server] [log_message:154] "POST /accounts/login/ HTTP/1.1" 200 1686
[25/Feb/2019 14:02:21] INFO [django.server] [log_message:154] "POST /accounts/login/ HTTP/1.1" 200 1686
[25/Feb/2019 14:02:21] INFO [django.server] [log_message:154] "POST /core/classify/ HTTP/1.1" 302 0
[25/Feb/2019 14:02:21] INFO [django.server] [log_message:154] "POST /core/classify/ HTTP/1.1" 302 0
[25/Feb/2019 14:02:21] INFO [django.server] [log_message:154] "GET /accounts/login/?next=/core/classify/ HTTP/1.1" 200 1685
[25/Feb/2019 14:02:21] INFO [django.server] [log_message:154] "GET /accounts/login/?next=/core/classify/ HTTP/1.1" 200 1685
[25/Feb/2019 14:02:42] INFO [django.server] [log_message:154] "GET / HTTP/1.1" 200 401
[25/Feb/2019 14:02:42] INFO [django.server] [log_message:154] "GET / HTTP/1.1" 200 401
[25/Feb/2019 14:02:44] INFO [django.server] [log_message:154] "GET /accounts/signup/ HTTP/1.1" 200 1143
[25/Feb/2019 14:02:44] INFO [django.server] [log_message:154] "GET /accounts/signup/ HTTP/1.1" 200 1143
[25/Feb/2019 14:02:59] ERROR [django.request] [log_response:228] Internal Server Error: /accounts/signup/
Traceback (most recent call last):
  File "C:\Python36\lib\site-packages\django\core\handlers\exception.py", line 34, in inner
    response = get_response(request)
  File "C:\Python36\lib\site-packages\django\core\handlers\base.py", line 126, in _get_response
    response = self.process_exception_by_middleware(e, request)
  File "C:\Python36\lib\site-packages\django\core\handlers\base.py", line 124, in _get_response
    response = wrapped_callback(request, *callback_args, **callback_kwargs)
  File "C:\Python36\lib\site-packages\django\views\generic\base.py", line 68, in view
    return self.dispatch(request, *args, **kwargs)
  File "C:\Python36\lib\site-packages\django\utils\decorators.py", line 45, in _wrapper
    return bound_method(*args, **kwargs)
  File "C:\Python36\lib\site-packages\django\views\decorators\debug.py", line 76, in sensitive_post_parameters_wrapper
    return view(request, *args, **kwargs)
  File "C:\Python36\lib\site-packages\allauth\account\views.py", line 214, in dispatch
    return super(SignupView, self).dispatch(request, *args, **kwargs)
  File "C:\Python36\lib\site-packages\allauth\account\views.py", line 80, in dispatch
    **kwargs)
  File "C:\Python36\lib\site-packages\allauth\account\views.py", line 192, in dispatch
    **kwargs)
  File "C:\Python36\lib\site-packages\django\views\generic\base.py", line 88, in dispatch
    return handler(request, *args, **kwargs)
  File "C:\Python36\lib\site-packages\allauth\account\views.py", line 103, in post
    response = self.form_valid(form)
  File "C:\Python36\lib\site-packages\allauth\account\views.py", line 235, in form_valid
    self.get_success_url())
  File "C:\Python36\lib\site-packages\allauth\account\utils.py", line 183, in complete_signup
    signal_kwargs=signal_kwargs)
  File "C:\Python36\lib\site-packages\allauth\account\utils.py", line 143, in perform_login
    send_email_confirmation(request, user, signup=signup)
  File "C:\Python36\lib\site-packages\allauth\account\utils.py", line 314, in send_email_confirmation
    signup=signup)
  File "C:\Python36\lib\site-packages\allauth\account\models.py", line 60, in send_confirmation
    confirmation.send(request, signup=signup)
  File "C:\Python36\lib\site-packages\allauth\account\models.py", line 166, in send
    get_adapter(request).send_confirmation_mail(request, self, signup)
  File "C:\Python36\lib\site-packages\allauth\account\adapter.py", line 450, in send_confirmation_mail
    ctx)
  File "C:\Python36\lib\site-packages\allauth\account\adapter.py", line 137, in send_mail
    msg.send()
  File "C:\Python36\lib\site-packages\django\core\mail\message.py", line 291, in send
    return self.get_connection(fail_silently).send_messages([self])
  File "C:\Python36\lib\site-packages\django\core\mail\backends\smtp.py", line 103, in send_messages
    new_conn_created = self.open()
  File "C:\Python36\lib\site-packages\django\core\mail\backends\smtp.py", line 63, in open
    self.connection = self.connection_class(self.host, self.port, **connection_params)
  File "C:\Python36\lib\smtplib.py", line 251, in __init__
    (code, msg) = self.connect(host, port)
  File "C:\Python36\lib\smtplib.py", line 336, in connect
    self.sock = self._get_socket(host, port, self.timeout)
  File "C:\Python36\lib\smtplib.py", line 307, in _get_socket
    self.source_address)
  File "C:\Python36\lib\socket.py", line 724, in create_connection
    raise err
  File "C:\Python36\lib\socket.py", line 713, in create_connection
    sock.connect(sa)
ConnectionRefusedError: [WinError 10061] No connection could be made because the target machine actively refused it
[25/Feb/2019 14:02:59] ERROR [django.server] [log_message:154] "POST /accounts/signup/ HTTP/1.1" 500 181248
[25/Feb/2019 14:02:59] ERROR [django.server] [log_message:154] "POST /accounts/signup/ HTTP/1.1" 500 181248
[25/Feb/2019 14:03:18] ERROR [django.request] [log_response:228] Internal Server Error: /accounts/signup/
Traceback (most recent call last):
  File "C:\Python36\lib\site-packages\django\core\handlers\exception.py", line 34, in inner
    response = get_response(request)
  File "C:\Python36\lib\site-packages\django\core\handlers\base.py", line 126, in _get_response
    response = self.process_exception_by_middleware(e, request)
  File "C:\Python36\lib\site-packages\django\core\handlers\base.py", line 124, in _get_response
    response = wrapped_callback(request, *callback_args, **callback_kwargs)
  File "C:\Python36\lib\site-packages\django\views\generic\base.py", line 68, in view
    return self.dispatch(request, *args, **kwargs)
  File "C:\Python36\lib\site-packages\django\utils\decorators.py", line 45, in _wrapper
    return bound_method(*args, **kwargs)
  File "C:\Python36\lib\site-packages\django\views\decorators\debug.py", line 76, in sensitive_post_parameters_wrapper
    return view(request, *args, **kwargs)
  File "C:\Python36\lib\site-packages\allauth\account\views.py", line 214, in dispatch
    return super(SignupView, self).dispatch(request, *args, **kwargs)
  File "C:\Python36\lib\site-packages\allauth\account\views.py", line 80, in dispatch
    **kwargs)
  File "C:\Python36\lib\site-packages\allauth\account\views.py", line 192, in dispatch
    **kwargs)
  File "C:\Python36\lib\site-packages\django\views\generic\base.py", line 88, in dispatch
    return handler(request, *args, **kwargs)
  File "C:\Python36\lib\site-packages\allauth\account\views.py", line 103, in post
    response = self.form_valid(form)
  File "C:\Python36\lib\site-packages\allauth\account\views.py", line 235, in form_valid
    self.get_success_url())
  File "C:\Python36\lib\site-packages\allauth\account\utils.py", line 183, in complete_signup
    signal_kwargs=signal_kwargs)
  File "C:\Python36\lib\site-packages\allauth\account\utils.py", line 143, in perform_login
    send_email_confirmation(request, user, signup=signup)
  File "C:\Python36\lib\site-packages\allauth\account\utils.py", line 314, in send_email_confirmation
    signup=signup)
  File "C:\Python36\lib\site-packages\allauth\account\models.py", line 60, in send_confirmation
    confirmation.send(request, signup=signup)
  File "C:\Python36\lib\site-packages\allauth\account\models.py", line 166, in send
    get_adapter(request).send_confirmation_mail(request, self, signup)
  File "C:\Python36\lib\site-packages\allauth\account\adapter.py", line 450, in send_confirmation_mail
    ctx)
  File "C:\Python36\lib\site-packages\allauth\account\adapter.py", line 137, in send_mail
    msg.send()
  File "C:\Python36\lib\site-packages\django\core\mail\message.py", line 291, in send
    return self.get_connection(fail_silently).send_messages([self])
  File "C:\Python36\lib\site-packages\django\core\mail\backends\smtp.py", line 103, in send_messages
    new_conn_created = self.open()
  File "C:\Python36\lib\site-packages\django\core\mail\backends\smtp.py", line 63, in open
    self.connection = self.connection_class(self.host, self.port, **connection_params)
  File "C:\Python36\lib\smtplib.py", line 251, in __init__
    (code, msg) = self.connect(host, port)
  File "C:\Python36\lib\smtplib.py", line 336, in connect
    self.sock = self._get_socket(host, port, self.timeout)
  File "C:\Python36\lib\smtplib.py", line 307, in _get_socket
    self.source_address)
  File "C:\Python36\lib\socket.py", line 724, in create_connection
    raise err
  File "C:\Python36\lib\socket.py", line 713, in create_connection
    sock.connect(sa)
ConnectionRefusedError: [WinError 10061] No connection could be made because the target machine actively refused it
[25/Feb/2019 14:03:18] ERROR [django.server] [log_message:154] "POST /accounts/signup/ HTTP/1.1" 500 181248
[25/Feb/2019 14:03:18] ERROR [django.server] [log_message:154] "POST /accounts/signup/ HTTP/1.1" 500 181248
[25/Feb/2019 14:03:29] INFO [django.server] [log_message:154] "GET /accounts/login/ HTTP/1.1" 200 1566
[25/Feb/2019 14:03:29] INFO [django.server] [log_message:154] "GET /accounts/login/ HTTP/1.1" 200 1566
[25/Feb/2019 14:03:30] INFO [django.server] [log_message:154] "POST /accounts/login/ HTTP/1.1" 302 0
[25/Feb/2019 14:03:30] INFO [django.server] [log_message:154] "POST /accounts/login/ HTTP/1.1" 302 0
[25/Feb/2019 14:03:30] ERROR [django.request] [log_response:228] Internal Server Error: /users/profile/
Traceback (most recent call last):
  File "C:\Python36\lib\site-packages\django\core\handlers\exception.py", line 34, in inner
    response = get_response(request)
  File "C:\Python36\lib\site-packages\django\utils\deprecation.py", line 93, in __call__
    response = self.process_response(request, response)
  File "C:\Python36\lib\site-packages\django\middleware\clickjacking.py", line 26, in process_response
    if response.get('X-Frame-Options') is not None:
  File "C:\Python36\lib\site-packages\django\utils\functional.py", line 214, in inner
    return func(self._wrapped, *args)
AttributeError: 'CustomUser' object has no attribute 'get'
[25/Feb/2019 14:03:30] ERROR [django.server] [log_message:154] "GET /users/profile/ HTTP/1.1" 500 69986
[25/Feb/2019 14:03:30] ERROR [django.server] [log_message:154] "GET /users/profile/ HTTP/1.1" 500 69986
[25/Feb/2019 14:03:34] INFO [core.views] [post:30] Some files are in the request, processing started..
[25/Feb/2019 14:03:39] INFO [ai.classification] [find_creator_and_verify_permissions:29] szabag@gmail.com requested a new classification
[25/Feb/2019 14:03:39] INFO [ai.classification] [save_picture_and_create_imagedata:34] Processing image file data 430.jpg 
[25/Feb/2019 14:03:39] INFO [ai.classification] [save_picture_and_create_imagedata:43] New imagefile saved with id 1 
[25/Feb/2019 14:03:39] INFO [ai.classification] [save_picture_and_create_imagedata:54] Image saved into C:\CR\IMAGES\szabag\ 
[25/Feb/2019 14:03:42] INFO [ai.classification] [classify:60] Classification started for image 430 by user szabag
